<mujoco model="ur5gripper">
    <compiler angle="radian"
              inertiafromgeom="true"
              texturedir="textures/"
              meshdir="mesh/visual/"/>
    <option timestep="2e-3"
            gravity="0 0 -9.81"
            iterations="25"
            tolerance="1e-7"
            impratio="1"
            cone="elliptic"
            solver="Newton"/>

        <size nconmax="5000" njmax="10000" nstack="5000000"/>
    <default>
        <site rgba="0.8 0.6 0.7 0.3" type="ellipsoid" group="3" />
        <geom contype='1' conaffinity='1' condim='1'  margin="1e-3" solref=".01 1" solimp=".99 .99 .001" />
<!--                <geom contype='1' conaffinity='1' condim='4'  margin="1e-3" solref="-100 -100" solimp="1 1 .001" />-->

<!--        <geom contype='1' conaffinity='1' condim='4' priority="1" margin="1e-3" solref="-100 -150" solimp="0.9999 0.9999 0.001 0.1 2" />-->

        <joint armature="0.01" damping=".1"/>
        <default class="UR5">
            <joint damping='65'/>
        </default>
        <default class="UR5e">
            <joint damping='45'/>
        </default>
        <default class="GRIPPER">
            <joint damping='5'/>
        </default>
    </default>

    <visual>
        <map fogstart="3" fogend="5" znear="0.05"/>
        <quality shadowsize="2048"/>
        <scale framelength="0.1"
               framewidth="0.005"
               contactwidth="0.1"
               contactheight="0.005"
               forcewidth="0.01"
               />
    </visual>

    <!--Assets-->
    <asset>
        <!--Meshes-->


	    <mesh file="Slot Assembly - Angle-1.STL" name="A1" scale="0.001 0.001 0.001"  />
	    <mesh file="Slot Assembly - Angle-2.STL" name="A2" scale="0.001 0.001 0.001"  />
		<mesh file="Slot Assembly - Angle-3.STL" name="A3" scale="0.001 0.001 0.001"  />
	    <mesh file="Slot Assembly - Angle-4.STL" name="A4" scale="0.001 0.001 0.001"  />
		<mesh file="Slot Assembly - Inner-1.STL" name="Inner" scale="0.001 0.001 0.001"  />
		<mesh file="Slot Assembly - OUTERLENGTH-1.STL" name="L1" scale="0.001 0.001 0.001"  />
	    <mesh file="Slot Assembly - OUTERLENGTH-2.STL" name="L2" scale="0.001 0.001 0.001"  />
		<mesh file="Slot Assembly - OUTERWIDTH-1.STL" name="W1" scale="0.001 0.001 0.001"  />
	    <mesh file="Slot Assembly - OUTERWIDTH-2.STL" name="W2" scale="0.001 0.001 0.001"  />
		 <mesh file="Slot Assembly - Part1-1.STL" name="Grip" scale="0.001 0.001 0.001"  />
		  <mesh file="Slot Assembly - Part2-1.STL" name="Grip2" scale="0.001 0.001 0.001"  />
		   <mesh file="Slot Assembly - Part2-2.STL" name="Grip3" scale="0.001 0.001 0.001"  />
		<mesh file="rubber.STL" name="rubber_mesh" scale="2e-3 2e-3 2e-3"/>
        <mesh name="base"           file="base.stl"     />
        <mesh name="shoulder"       file="shoulder.stl" />
        <mesh name="upperarm"       file="upperarm.stl" />
        <mesh name="forearm"        file="forearm.stl"  />
        <mesh name="wrist1"         file="wrist1.stl"   />
        <mesh name="wrist2"         file="wrist2.stl"   />
        <mesh name="wrist3"         file="wrist3.stl"   />
        <mesh name="gripperpalm"    file="palm.STL"     />
        <mesh name="link_0"         file="link_0.STL"   />
        <mesh name="link_1"         file="link_1.STL"   />
        <mesh name="link_2"         file="link_2.STL"   />
        <mesh name="link_3"         file="link_3.STL"   />
        <mesh name="dummy_gripper"         file="dummyGripper.STL"   />



		<!--New Gripper-->
		<mesh name="kinova_robotiq_coupler" file="kinova_robotiq_coupler.stl" />
        <mesh name="robotiq_85_base_link" file="robotiq_85_base_link.stl" />
        <mesh name="robotiq_85_knuckle_link" file="robotiq_85_knuckle_link.stl" />
        <mesh name="robotiq_85_finger_link" file="robotiq_85_finger_link.stl" />
        <mesh name="robotiq_85_finger_tip_link" file="robotiq_85_finger_tip_link.stl" />
        <mesh name="robotiq_85_inner_knuckle_link" file="robotiq_85_inner_knuckle_link.stl" />
		
        <material name="RobMat" emission="0.1" specular="0.9" rgba="0.7 0.7 0.7 1" />
        <material name="GriMat" emission="0.1" specular="0.9" rgba="0.7 0.7 0.7 1" />
        <material name="BasketMat" specular="0" shininess="0" rgba="0.26 0.16 0.167969 1" />
        <material name="Light" emission="0.7" specular="0" shininess="0.6" reflectance="0.9" rgba="0.5 0.5 1 1" />
        <!--Textures-->

        <texture name="ur5_tex"     type="2d"       builtin="flat" height="32" width="32" rgb1="0.9 0.9 0.9" />
        <texture name="gripper_tex" type="2d"       builtin="flat" height="32" width="32" rgb1="0.9 0.9 0.9" rgb2="0 0 0"/>
        <texture name="bench_tex"   type="2d"       builtin="flat" height="32" width="32" rgb1="0.7 0.7 0.7" />
        <texture name="sky_tex"     type="skybox"   builtin="gradient" width="100" height="100" rgb1="1 1 1" rgb2="0.3 0.3 0.8" />
        <texture name="texgeom"     type="cube"     builtin="flat" mark="cross" width="127" height="1278" rgb1="0.8 0.6 0.4" rgb2="0.8 0.6 0.4" markrgb="1 1 1" random="0.01" />
        <texture name="floor_tex"   type="2d"        builtin="checker" rgb1=".2 .3 .4" rgb2=".1 .2 .3" width="100" height="100" />
        <texture name="wood"        type="cube"     file="wood2.png"/>
        <texture name="metal"        type="cube"     file="metal2.png"/>
        <texture name="texsponge" type="2d" file="sponge.png"/>
        <!--Materials-->
        <material name="ur5_mat"        texture="ur5_tex"   shininess="0.9" specular="0.75" reflectance="0.3"/>
        <material name="gripper_mat"    texture="gripper_tex"   shininess="0.9" specular="0.75" reflectance="0.4"/>
        <material name='floor_mat'      texture="floor_tex"  shininess="0.8" texrepeat="10 10" specular="0.7"  reflectance="0.5" />
        <material name='geom'           texture="texgeom"   texuniform="true" />
        <material name="bench_mat"      texture="metal"   shininess="0.1" specular="0.5" reflectance="0.2"/>
        <material name="tablecube"      texture="wood" rgba=".8 .8 .8 1"/>
        <material name="matsponge" texture="texsponge" specular="0.3"/>
    </asset>

    <!--Contacts-->
    <contact>
        <!-- <exclude body1="gripperpalm" body2="gripperfinger_1_link_1"/> -->
		<!-- <exclude body1="gripperpalm" body2="gripperfinger_2_link_1"/> -->
		<!-- <exclude body1="gripperpalm" body2="gripperfinger_middle_link_1"/> -->
        <exclude body1="box_link" body2="base_link"/>
		<exclude body1="base_link" body2="shoulder_link"/>
		<exclude body1="shoulder_link" body2="upper_arm_link"/>
        <exclude body1="upper_arm_link" body2="forearm_link"/>
		<exclude body1="forearm_link" body2="wrist_1_link"/>
		<exclude body1="wrist_1_link" body2="wrist_2_link"/>
        <exclude body1="wrist_2_link" body2="wrist_3_link"/>
        <!-- <exclude body1="wrist_3_link" body2="gripperpalm"/> -->
        <exclude body1="ee_link" body2="wrist_3_link"/>
        <exclude body1="ee_link" body2="dummy_gripper"/>
        <exclude body1="dummy_gripper" body2="wrist_3_link"/>
        <exclude body1="dummy_gripper" body2="wrist_2_link"/>
        <exclude body1="dummy_gripper" body2="wrist_1_link"/>
<!--        <exclude body1="dummy_gripper" body2="Slot"/>-->


        <!--        <exclude body1="dummy_gripper" body2="Slot"/>-->

<!--        <exclude body1="dummy_gripper" body2="B0"/>-->
<!--        <exclude body1="dummy_gripper" body2="box_link"/>-->
<!--        <exclude body1="dummy_gripper" body2="base_link"/>-->

    </contact>

    <!--MODEL DESCRIPTION-->
    <worldbody>
        <!--Lighting parameters-->
        <light name="light3" mode="targetbody" target="box_link" directional="true" pos="1 1 3" />
        <!--Camera parameters-->
        <camera mode="targetbody" target="dummy_gripper" pos="0 0 0" axisangle="0 0 1 0"/>
        <!--Floor Property-->
        <geom name='floor' material="floor_mat" pos='0 0 0' size='2.5 2.5 0.1'  type='plane' />

        <!--Robot UR5-->




   <body name="box_link" pos="0 0 0.420">
            <!--<geom size=".3 .2 .435" type="box" material="bench_mat"/>-->
            <geom size="0.8 0.8 .03" pos ="0 0 0.4" type="box" material="bench_mat"/>
            <geom size="0.8 0.8 .03" pos ="0 0 -0.2" type="box" material="bench_mat"/>
            <geom size=".04 .04 .435" pos =".26 .16 0" type="box" material="bench_mat"/>
            <geom size=".04 .04 .435" pos ="-.26 .16 0" type="box" material="bench_mat"/>
            <geom size=".04 .04 .435" pos =".26 -.16 0" type="box" material="bench_mat"/>
            <geom size=".04 .04 .435" pos ="-.26 -.16 0" type="box" material="bench_mat"/>
            <site name="box_link_site" pos="0 0 0.42" size="0.035 0.0055 0.035"/>
            <inertial pos="0 0 0" mass="1000" diaginertia="0 0 0" />
            <body name="base_link" pos="0 0 0.435">
                <inertial pos="0 0 0" quat="0.5 0.5 -0.5 0.5" mass="4" diaginertia="0.0072 0.00443333 0.00443333" />
                <geom type="mesh"  mesh="base" material="ur5_mat"/>
                <body name="shoulder_link" pos="0 0 0.089159">
                    <inertial pos="0 0 0" mass="3.7" diaginertia="0.0102675 0.0102675 0.00666" />
                    <joint name="shoulder_pan_joint" class="UR5" pos="0 0 0" axis="0 0 1" limited="true" range="-6.29 6.29" />
                    <geom type="mesh"  mesh="shoulder" material="ur5_mat"/>
                    <body name="upper_arm_link" pos="0 0.13585 0" quat="0.707107 0 0.707107 0">
                        <inertial pos="0 0 0.28" mass="8.393" diaginertia="0.226891 0.226891 0.0151074" />
                        <joint name="shoulder_lift_joint" class="UR5" pos="0 0 0" axis="0 1 0" limited="true" range="-6.29 6.29" /> <!--Range= -3.14159 3.14159-->
                        <geom type="mesh"  mesh="upperarm" material="ur5_mat"/>
                        <body name="forearm_link" pos="0 -0.1197 0.425">
                            <inertial pos="0 0 0.25" mass="2.275" diaginertia="0.0494433 0.0494433 0.004095" />
                            <joint name="elbow_joint" class="UR5" pos="0 0 0" axis="0 1 0" limited="true" range="-6.29 6.29" />
                            <geom type="mesh"  mesh="forearm" material="ur5_mat"/>
                            <body name="wrist_1_link" pos="0 0 0.39225" quat="0.707107 0 0.707107 0">
                                <inertial pos="0 0 0" quat="0.5 0.5 -0.5 0.5" mass="1.219" diaginertia="0.21942 0.111173 0.111173" />
                                <joint name="wrist_1_joint" class="UR5e" pos="0 0 0" axis="0 1 0" limited="true" range="-6.29 6.29" />
                                <geom type="mesh"  mesh="wrist1" material="ur5_mat"/>
                                <body name="wrist_2_link" pos="0 0.093 0">
                                    <inertial pos="0 0 0" quat="0.5 0.5 -0.5 0.5" mass="1.219" diaginertia="0.21942 0.111173 0.111173" />
                                    <joint name="wrist_2_joint" class="UR5e" pos="0 0 0" axis="0 0 1" limited="true" range="-6.29 6.29" />
                                    <geom type="mesh"  mesh="wrist2" material="ur5_mat"/>
                                    <body name="wrist_3_link" pos="0 0 0.09465">
                                        <inertial pos="0 0 0" quat="0.5 0.5 -0.5 0.5" mass="0.1879" diaginertia="0.033822 0.0171365 0.0171365" />
                                        <joint name="wrist_3_joint" class="UR5e" pos="0 0 0" axis="0 1 0" limited="true" range="-6.29 6.29" />
                                        <geom type="mesh"  mesh="wrist3" material="ur5_mat"/>
                                        <body name="ee_link" pos="0 0.0823 0" quat="0.707107 0 0 0.707107">
                                            <inertial pos="-0.01 0 0" mass="0.001" diaginertia="1.66667e-08 1.66667e-08 1.66667e-08" />
                                            <geom size="0.005 0.005 0.005" pos="-0.01 0 0" type="box" />
                                        </body>
                                        <!--GRIPPER-->
<!--                                        <body name="tool0" pos="0 0.0823 0" quat="0.707107 -0.707107 0 0">-->
                                        <body name="tool0" >
<!--                                            <inertial pos="0 0 0" mass="0.1879" diaginertia="0.033822 0.0171365 0.0171365" />-->
<!--                                            <body name="dummy_gripper" pos="-0.0315 0.0823 -0.0315">-->
<!--                                                <site name="gripper_finger" pos="0 0.0823 0" size=".005 .005 .005" type="box"/>-->
                                            <body name="dummy_gripper" pos="0 0.0823 0" quat="0.707107 -0.707107 0 0">
                                                <site name="gripper_finger" pos="0 0 0.1" size=".001 .001 .001" type="box"/>

<!--                                                <site name="gripper_finger" pos="0.0315 0.1 0.0315" size=".115 .115 .115" type="box"/>-->
<!--                                                <inertial pos="0 0.001568975 0" mass="0.255" diaginertia="9.177e-5 0.00012461 9.177e-5" />-->
<!--                                                <geom name="gripper_geom" type="mesh"  mesh="dummy_gripper" material="gripper_mat"/>-->
<!--                                                <geom name="gripper_geom" type="capsule" size=".0015 0.1" />-->
                                                <geom name="gripper_geom" type="cylinder" size=".0015 0.1" />
<!--                                                <body name="test" pos="0 0 0.1">-->
<!--                                                    <geom name="test2" type="cylinder" size=".0005 0.005" rgba=".8 .2 .1 1" />-->
<!--                                                </body>-->
                                            </body>

                                        </body>
                                    </body>
                                </body>
                            </body>
                        </body>
                    </body>
                </body>
                <body name="base" pos="0 0 0" quat="1.7949e-09 0 0 -1">
                    <inertial pos="0 0 0" quat="1.7949e-09 0 0 -1" mass="0" diaginertia="0 0 0" />
                </body>
            </body>
        </body>



<!--	   <body name="Slot" pos="0.1 0.6 0.851">-->
<!--        <inertial pos="0 0 0" mass="1000" diaginertia="1000 1000 1000" />-->
<!--		<geom pos="0 0 0" friction="0.5 0.5 0.5" solref="-1e3 -5e2" solimp="0.99 0.99 0.01" mesh="L1" type="mesh" rgba="0 1 0 1" group="1" mass="1000.0000001" zaxis="0 -1 0"/>-->
<!--		<geom pos="0 0 0" friction="0.5 0.5 0.5" solref="-1e3 -5e2" solimp="0.99 0.99 0.01" mesh="L2" type="mesh" rgba="0 1 0 1" group="1" mass="1000.0000001" zaxis="0 -1 0"/>-->
<!--		<geom pos="0 0 0" friction="0.5 0.5 0.5" solref="-1e3 -5e2" solimp="0.99 0.99 0.01" mesh="W1" type="mesh" rgba="0 1 0 1" group="1" mass="1000.0000001" zaxis="0 -1 0"/>-->
<!--		<geom pos="0 0 0" friction="0.5 0.5 0.5" solref="-1e3 -5e2" solimp="0.99 0.99 0.01" mesh="W2" type="mesh" rgba="0 1 0 1" group="1" mass="1000.0000001" zaxis="0 -1 0"/>-->
<!--		<geom pos="0 0 0" friction="0.5 0.5 0.5" solref="-1e3 -5e2" solimp="0.99 0.99 0.01" mesh="A1" type="mesh" rgba="0 1 0 1" group="1" mass="1000.0000001" zaxis="0 -1 0"/>-->
<!--		<geom pos="0 0 0" friction="0.5 0.5 0.5" solref="-1e3 -5e2" solimp="0.99 0.99 0.01" mesh="A2" type="mesh" rgba="0 1 0 1" group="1" mass="1000.0000001" zaxis="0 -1 0"/>-->
<!--		<geom pos="0 0 0" friction="0.5 0.5 0.5" solref="-1e3 -5e2" solimp="0.99 0.99 0.01" mesh="A3" type="mesh" rgba="0 1 0 1" group="1" mass="1000.0000001" zaxis="0 -1 0"/>-->
<!--		<geom pos="0 0 0" friction="0.5 0.5 0.5" solref="-1e3 -5e2" solimp="0.99 0.99 0.01" mesh="A4" type="mesh" rgba="0 1 0 1" group="1" mass="1000.0000001" zaxis="0 -1 0"/>-->
<!--		<geom pos="0 0 0" friction="0.5 0.5 0.5" solref="-1e3 -5e2" solimp="0.99 0.99 0.01" mesh="Inner" type="mesh" rgba="0 1 0 1" group="1" mass="0.0001" zaxis="0 -1 0"/>-->
<!--		</body>-->

	   <body name="Slot" pos="-0.2 0.5 0.851">
        <inertial pos="0 0 0" mass="1e6" diaginertia="0 0 0" />
		<geom pos="0 0 0"  mesh="L1" type="mesh" rgba="0 1 0 1" group="1" zaxis="0 -1 0"/>
		<geom pos="0 0 0"  mesh="L2" type="mesh" rgba="0 1 0 1" group="1" zaxis="0 -1 0"/>
		<geom pos="0 0 0"  mesh="W1" type="mesh" rgba="0 1 0 1" group="1" zaxis="0 -1 0"/>
		<geom pos="0 0 0"  mesh="W2" type="mesh" rgba="0 1 0 1" group="1" zaxis="0 -1 0"/>
		<geom pos="0 0 0"  mesh="A1" type="mesh" rgba="0 1 0 1" group="1" zaxis="0 -1 0"/>
		<geom pos="0 0 0"  mesh="A2" type="mesh" rgba="0 1 0 1" group="1" zaxis="0 -1 0"/>
		<geom pos="0 0 0"  mesh="A3" type="mesh" rgba="0 1 0 1" group="1" zaxis="0 -1 0"/>
		<geom pos="0 0 0"  mesh="A4" type="mesh" rgba="0 1 0 1" group="1" zaxis="0 -1 0"/>
		<geom pos="0 0 0"  name="Inner" mesh="Inner" type="mesh" rgba="0 1 0 1" group="1" zaxis="0 -1 0"/>
		</body>

<!--        <body name="B0" pos="0.0445 0.361 0.874">-->
        <body name="B0" pos="-0.1555 0.261 0.874">
<!--        <body name="B0" pos="0.1445 0.39 0.874">-->
            <freejoint/>
            <composite type="rope" count="25 1 1" spacing="0.0125" offset="0 0 0">
                    <joint kind="main"  damping="0.0002" />
                <geom type="capsule" mass="20e-3" size=".0043 0.0045" priority="2" condim="3" rgba=".8 .2 .1 1" friction="0.8 0.005 0.0001" solref="-0.01 -700" solimp="0.95 0.999 .0012 0.5 1" />
            </composite>
        </body>
<!--        <body name="SB0" pos="0.0395 0.370 0.874" quat="0.707107 0 0 0.707107">-->
        <body name="SB0" pos="-0.1605 0.270 0.874" quat="0.707107 0 0 0.707107">
<!--        <body name="B0" pos="0.1445 0.39 0.874">-->
            <freejoint/>
            <composite prefix="S" type="rope" count="15 1 1" spacing="0.0125" offset="0 0 0">
                    <joint kind="main"  damping="0.002" />
                <geom type="capsule" mass="20e-3" size=".0043 0.0045" priority="2" condim="3" rgba=".8 .2 .1 1" friction="0.8 0.005 0.0001" solref="-0.01 -700" solimp="0.95 0.999 .0012 0.5 1" />
            </composite>
        </body>
        <body name="TB0" pos="0.151 0.270 0.874" quat="0.707107 0 0 0.707107">
<!--        <body name="B0" pos="0.1445 0.39 0.874">-->
            <freejoint/>
            <composite prefix="T" type="rope" count="15 1 1" spacing="0.0125" offset="0 0 0">
                    <joint kind="main"  damping="0.002" />
                <geom type="capsule" mass="20e-3" size=".0043 0.0045" priority="2" condim="3" rgba=".8 .2 .1 1" friction="0.8 0.005 0.0001" solref="-0.01 -700" solimp="0.95 0.999 .0012 0.5 1" />
            </composite>
        </body>
    </worldbody>


    <tendon>

	</tendon>

    <equality>
		<!-- GRIPPER Couplings -->
<!--        <joint name="right_1" joint1="joint7_1" joint2="joint9_1" polycoef="0 -2.933333 0 0 0" />-->
        <weld name="Rope1" body1="B0" body2="SB0" relpose="0 1 0 0 0 0 0"/>
        <weld name="Rope2" body1="B24" body2="TB0" relpose="0 1 0 0 0 0 0"/>

<!--		<tendon name="right1" 	tendon1="right1"/>-->
<!--		<tendon name="right2" 	tendon1="right2"/>-->
<!--        <tendon name="right3" 	tendon1="right3"/>-->
<!--		<tendon name="left1" 	tendon1="left1"/>-->
<!--		<tendon name="left2" 	tendon1="left2"/>-->
<!--        <tendon name="left3" 	tendon1="left3"/>-->
		<!-- SCISSOR Coupling -->
		<!-- <joint name="finger_12_scissor" joint1="gripperpalm_finger_2_joint" joint2="gripperpalm_finger_1_joint" polycoef="0 -1 0 0 0"/> -->
	</equality>


    <!--ACTUATORS-->
    <actuator>
        <!--UR5-->
        <!--<position name='shoulder_pan' ctrllimited="true" ctrlrange="-3.14159 3.14159" joint='shoulder_pan_joint' kp="500"/>-->
        <!--<position name='shoulder_lift' ctrllimited="true" ctrlrange="-3.14159 3.14159" joint='shoulder_lift_joint' kp="500"/>-->
        <!--<position name='forearm' ctrllimited="true" ctrlrange="-3.14159 3.14159" joint='elbow_joint' kp="500"/>-->
        <!--<position name='wrist_1' ctrllimited="true" ctrlrange="-3.14159 3.14159" joint='wrist_1_joint' kp="100"/>-->
        <!--<position name='wrist_2' ctrllimited="true" ctrlrange="-3.14159 3.14159" joint='wrist_2_joint' kp="100"/>-->
        <!--<position name='wrist_3' ctrllimited="true" ctrlrange="-3.14159 3.14159" joint='wrist_3_joint' kp="100"/>-->

        <motor name='shoulder_pan_T' ctrllimited="true" ctrlrange="-2 2" joint='shoulder_pan_joint' gear="101"/> <!--range -150 150-->
        <motor name='shoulder_lift_T' ctrllimited="true" ctrlrange="-2 2" joint='shoulder_lift_joint' gear="101"/>
        <motor name='forearm_T' ctrllimited="true" ctrlrange="-2 2" joint='elbow_joint' gear="101" />
        <motor name='wrist_1_T' ctrllimited="true" ctrlrange="-1 1" joint='wrist_1_joint' gear="101"/>  <!--range -28 28-->
        <motor name='wrist_2_T' ctrllimited="true" ctrlrange="-1 1" joint='wrist_2_joint' gear="101"/>
        <motor name='wrist_3_T' ctrllimited="true" ctrlrange="-1 1" joint='wrist_3_joint' gear="101"/>

        <!--<velocity name='shoulder_pan_v' class="UR5" joint='shoulder_pan_joint' kv="10"/>-->
        <!--<velocity name='shoulder_lift_v' class="UR5" joint='shoulder_lift_joint' />-->
        <!--<velocity name='forearm_v' class="UR5" joint='elbow_joint' />-->
        <!--<velocity name='wrist_1_v' class="UR5" joint='wrist_1_joint' />-->
        <!--<velocity name='wrist_2_v' class="UR5" joint='wrist_2_joint'/>-->
        <!--<velocity name='wrist_3_v' class="UR5" joint='wrist_3_joint'/>-->

        <!--Gripper-->
        <!--<position name='finger_1' ctrllimited="true" kp="20" joint='gripperfinger_1_joint_1' ctrlrange='0 1.2217'/>-->
        <!--<position name='finger_2' ctrllimited="true" kp="20" joint='gripperfinger_2_joint_1' ctrlrange='0 1.2217'/>-->
        <!--<position name='middle_finger'  ctrllimited="true" kp="20" joint='gripperfinger_middle_joint_1' ctrlrange='0 1.2217'/>-->
        <!--<position name='finger_scissor' ctrllimited="true" kp="20" joint='gripperpalm_finger_spo1_joint' ctrlrange="-0.2967 0.2967"/>-->


<!--        <motor name='finger_1_T' ctrllimited="true" joint='joint7_1' ctrlrange='0 .4' gear="10"/>-->
<!--        <motor name='finger_2_T' ctrllimited="true" joint='joint7_2' ctrlrange='0 .4' gear="10"/>-->
        <!-- <motor name='middle_finger_T'  ctrllimited="true" joint='gripperfinger_middle_joint_1' ctrlrange='-0.1 .8' gear="20"/> -->
        <!-- <motor name='finger_scissor_T' ctrllimited="true" joint='gripperpalm_finger_1_joint' ctrlrange="-0.8 0.8" gear="15"/> -->
    </actuator>

    <sensor>
<!--                <force name="gripper_sensor"	site="gripper_finger"/>-->
<!--                <velocimeter name="gripper_velocity"	site="gripper_finger"/>-->
                <touch name="gripper_touch_sensor" 	site="gripper_finger"/>

<!--        <force name="gripperpalm_frc" 		site="gripperpalm"/>-->
<!--        <force name="finger_1_polp_1_frc"	site="gripperfinger_1_polp_1"/>-->
<!--    	<force name="finger_1_polp_2_frc" 	site="gripperfinger_1_polp_2"/>-->
<!--        <force name="finger_1_polp_3_frc" 	site="gripperfinger_1_polp_3"/>-->

<!--        <force name="finger_2_link_1_frc" 	site="gripperfinger_2_polp_1"/>-->
<!--        <force name="finger_2_link_2_frc" 	site="gripperfinger_2_polp_2"/>-->
<!--        <force name="finger_2_link_3_frc" 	site="gripperfinger_2_polp_3"/>-->

<!--        <force name="finger_middle_link_1_frc" 	site="gripperfinger_middle_polp_1"/>-->
<!--        <force name="finger_middle_link_2_frc" 	site="gripperfinger_middle_polp_2"/>-->
<!--        <force name="finger_middle_link_3_frc" 	site="gripperfinger_middle_polp_3"/>-->


        <!-- <touch name="finger_1_polp_3_frc" 	site="gripperfinger_1_polp_3"/> -->

<!--        <force name="finger_2_link_1_frc" 	site="gripperfinger_2_polp_1"/>-->
<!--        <force name="finger_2_link_2_frc" 	site="gripperfinger_2_polp_2"/>-->
        <!-- <touch name="finger_2_link_3_frc" 	site="gripperfinger_2_polp_3"/> -->

<!--        <force name="finger_middle_link_1_frc" 	site="gripperfinger_middle_polp_1"/>-->
<!--        <force name="finger_middle_link_2_frc" 	site="gripperfinger_middle_polp_2"/>-->
        <!-- <touch name="finger_middle_link_3_frc" 	site="gripperfinger_middle_polp_3"/> -->
    </sensor>
</mujoco>